Workbook
Name Slicer_Campaign_Name: #N/A
Name Slicer_Content_Type: #N/A
Name Slicer_Content_Type1: #N/A
Name Slicer_Platform: #N/A

Sheet Post(hashtag)
A1: Post ID | B1: Platform | C1: Date | D1: Content Type | E1: Post Text | F1: Likes | G1: Shares | H1: Comments | I1: Impressions | J1: Reach | K1: Clicks | L1: Hashtags Used | M1: Campaign_Name | N1: Engagement_Rate
A2: P001 | B2: Twitter | C2: 45649 | D2: Reel | E2: Explore the latest reel on Myntra! Trendy styles await. | F2: 1461 | G2: 184 | H2: 344 | I2: 21915 | J2: 21675 | K2: 15 | L2: #MyntraSale | M2: FashionUpgrade | N2: 9.08
A3: P002 | B3: Twitter | C3: 45750 | D3: Text | E3: Explore the latest text on Myntra! Trendy styles await. | F3: 4054 | G3: 389 | H3: 493 | I3: 64864 | J3: 64383 | K3: 117 | L3: #MyntraFashion | M3: EndOfSeasonSale | N3: 7.61
A4: P003 | B4: YouTube | C4: 45789 | D4: Reel | E4: Explore the latest reel on Myntra! Trendy styles await. | F4: 2795 | G4: 105 | H4: 49 | I4: 53105 | J4: 52307 | K4: 204 | L4: #MyntraFashion | M4: FashionUpgrade | N4: 5.55
A5: P003 | B5: YouTube | C5: 45789 | D5: Reel | E5: Explore the latest reel on Myntra! Trendy styles await. | F5: 2795 | G5: 105 | H5: 49 | I5: 53105 | J5: 52307 | K5: 204 | L5: #MyntraSale | M5: FashionUpgrade | N5: 5.55
A6: P004 | B6: Instagram | C6: 45516 | D6: Story | E6: Explore the latest story on Myntra! Trendy styles await. | F6: 2404 | G6: 363 | H6: 138 | I6: 19232 | J6: 18636 | K6: 128 | L6: #MyntraSale | M6: FashionUpgrade | N6: 15.11
A7: P005 | B7: YouTube | C7: 45469 | D7: Reel | E7: Explore the latest reel on Myntra! Trendy styles await. | F7: 3557 | G7: 687 | H7: 424 | I7: 71140 | J7: 70701 | K7: 224 | L7: #StyleWithMyntra | M7: MyntraFestiveEdit | N7: 6.56
A8: P005 | B8: YouTube | C8: 45469 | D8: Reel | E8: Explore the latest reel on Myntra! Trendy styles await. | F8: 3557 | G8: 687 | H8: 424 | I8: 71140 | J8: 70701 | K8: 224 | L8: #MyntraFashion | M8: MyntraFestiveEdit | N8: 6.56
A9: P006 | B9: Facebook | C9: 45596 | D9: Carousel | E9: Explore the latest carousel on Myntra! Trendy styles await. | F9: 2945 | G9: 930 | H9: 355 | I9: 23560 | J9: 23275 | K9: 256 | L9: #MyntraTrend | M9: EndOfSeasonSale | N9: 17.95
A10: P007 | B10: Twitter | C10: 45467 | D10: Carousel | E10: Explore the latest carousel on Myntra! Trendy styles await. | F10: 3860 | G10: 201 | H10: 279 | I10: 61760 | J10: 61660 | K10: 235 | L10: #MyntraTrend | M10: MyntraFestiveEdit | N10: 7.03
A11: P008 | B11: YouTube | C11: 45486 | D11: Image | E11: Explore the latest image on Myntra! Trendy styles await. | F11: 3929 | G11: 262 | H11: 278 | I11: 43219 | J11: 42841 | K11: 39 | L11: #MyntraFashion | M11: MyntraFestiveEdit | N11: 10.34
A12: P008 | B12: YouTube | C12: 45486 | D12: Image | E12: Explore the latest image on Myntra! Trendy styles await. | F12: 3929 | G12: 262 | H12: 278 | I12: 43219 | J12: 42841 | K12: 39 | L12: #MyntraSale | M12: MyntraFestiveEdit | N12: 10.34
A13: P009 | B13: Facebook | C13: 45534 | D13: Text | E13: Explore the latest text on Myntra! Trendy styles await. | F13: 3784 | G13: 808 | H13: 404 | I13: 56760 | J13: 56343 | K13: 131 | L13: #MyntraFashion | M13: MyntraFestiveEdit | N13: 8.8
... A457: P300 | B457: Twitter | C457: 45535 | D457: Carousel | E457: Explore the latest carousel on Myntra! Trendy styles await. | F457: 4494 | G457: 717 | H457: 45 | I457: 62916 | J457: 62688 | K457: 191 | L457: #MyntraFashion | M457: FashionUpgrade | N457: 8.35

Sheet post(Engagemeent)
A1: Post ID | B1: Platform | C1: Date | D1: Content Type | E1: Post Text | F1: Likes | G1: Shares | H1: Comments | I1: Impressions | J1: Reach | K1: Clicks | L1: Hashtags Used | M1: Campaign_Name | N1: Engagement_Rate | O1: campaign_Start_Date | P1: Campaign_End_Date | Q1: Campaign phase
A2: P001 | B2: Twitter | C2: 45649 | D2: Reel | E2: Explore the latest reel on Myntra! Trendy styles await. | F2: 1461 | G2: 184 | H2: 344 | I2: 21915 | J2: 21675 | K2: 15 | L2: #MyntraSale | M2: FashionUpgrade | N2: 9.08 | O2: 45505 | P2: 45535 | Q2: After Campaign
A3: P003 | B3: YouTube | C3: 45789 | D3: Reel | E3: Explore the latest reel on Myntra! Trendy styles await. | F3: 2795 | G3: 105 | H3: 49 | I3: 53105 | J3: 52307 | K3: 204 | L3: #MyntraFashion,#MyntraSale | M3: FashionUpgrade | N3: 5.55 | O3: 45505 | P3: 45535 | Q3: After Campaign
A4: P004 | B4: Instagram | C4: 45516 | D4: Story | E4: Explore the latest story on Myntra! Trendy styles await. | F4: 2404 | G4: 363 | H4: 138 | I4: 19232 | J4: 18636 | K4: 128 | L4: #MyntraSale | M4: FashionUpgrade | N4: 15.11 | O4: 45505 | P4: 45535 | Q4: During Campaign
A5: P002 | B5: Twitter | C5: 45750 | D5: Text | E5: Explore the latest text on Myntra! Trendy styles await. | F5: 4054 | G5: 389 | H5: 493 | I5: 64864 | J5: 64383 | K5: 117 | L5: #MyntraFashion | M5: EndOfSeasonSale | N5: 7.61 | O5: 45453 | P5: 45478 | Q5: After Campaign
A6: P005 | B6: YouTube | C6: 45469 | D6: Reel | E6: Explore the latest reel on Myntra! Trendy styles await. | F6: 3557 | G6: 687 | H6: 424 | I6: 71140 | J6: 70701 | K6: 224 | L6: #StyleWithMyntra,#MyntraFashion | M6: MyntraFestiveEdit | N6: 6.56 | O6: 45570 | P6: 45601 | Q6: Before Campaign
A7: P006 | B7: Facebook | C7: 45596 | D7: Carousel | E7: Explore the latest carousel on Myntra! Trendy styles await. | F7: 2945 | G7: 930 | H7: 355 | I7: 23560 | J7: 23275 | K7: 256 | L7: #MyntraTrend | M7: EndOfSeasonSale | N7: 17.95 | O7: 45453 | P7: 45478 | Q7: After Campaign
A8: P007 | B8: Twitter | C8: 45467 | D8: Carousel | E8: Explore the latest carousel on Myntra! Trendy styles await. | F8: 3860 | G8: 201 | H8: 279 | I8: 61760 | J8: 61660 | K8: 235 | L8: #MyntraTrend | M8: MyntraFestiveEdit | N8: 7.03 | O8: 45570 | P8: 45601 | Q8: Before Campaign
A9: P008 | B9: YouTube | C9: 45486 | D9: Image | E9: Explore the latest image on Myntra! Trendy styles await. | F9: 3929 | G9: 262 | H9: 278 | I9: 43219 | J9: 42841 | K9: 39 | L9: #MyntraFashion,#MyntraSale | M9: MyntraFestiveEdit | N9: 10.34 | O9: 45570 | P9: 45601 | Q9: Before Campaign
A10: P009 | B10: Facebook | C10: 45534 | D10: Text | E10: Explore the latest text on Myntra! Trendy styles await. | F10: 3784 | G10: 808 | H10: 404 | I10: 56760 | J10: 56343 | K10: 131 | L10: #MyntraFashion,#MyntraSale | M10: MyntraFestiveEdit | N10: 8.8 | O10: 45570 | P10: 45601 | Q10: Before Campaign
A11: P010 | B11: Facebook | C11: 45727 | D11: Image | E11: Explore the latest image on Myntra! Trendy styles await. | F11: 4241 | G11: 902 | H11: 47 | I11: 72097 | J11: 71598 | K11: 167 | L11: #MyntraTrend | M11: StyleRevolution | N11: 7.2 | O11: 45667 | P11: 45698 | Q11: After Campaign
A12: P011 | B12: Instagram | C12: 45690 | D12: Story | E12: Explore the latest story on Myntra! Trendy styles await. | F12: 1792 | G12: 614 | H12: 497 | I12: 25088 | J12: 24675 | K12: 65 | L12: #StyleWithMyntra | M12: FashionUpgrade | N12: 11.57 | O12: 45505 | P12: 45535 | Q12: After Campaign
A13: P012 | B13: Facebook | C13: 45494 | D13: Reel | E13: Explore the latest reel on Myntra! Trendy styles await. | F13: 1946 | G13: 686 | H13: 377 | I13: 23352 | J13: 22982 | K13: 213 | L13: #StyleWithMyntra,#MyntraSale | M13: MyntraFestiveEdit | N13: 12.89 | O13: 45570 | P13: 45601 | Q13: Before Campaign
... A55: P054 | B55: YouTube | C55: 45729 | D55: Carousel | E55: Explore the latest carousel on Myntra! Trendy styles await. | F55: 1686 | G55: 904 | H55: 472 | I55: 18546 | J55: 18171 | K55: 52 | L55: #MyntraFashion,#FashionDeals | M55: EndOfSeasonSale | N55: 16.51 | O55: 45453 | P55: 45478 | Q55: After Campaign
A56: P055 | B56: Facebook | C56: 45460 | D56: Image | E56: Explore the latest image on Myntra! Trendy styles await. | F56: 1226 | G56: 119 | H56: 7 | I56: 14712 | J56: 14049 | K56: 123 | L56: #MyntraSale,#MyntraTrend | M56: StyleRevolution | N56: 9.19 | O56: 45667 | P56: 45698
A57: P056 | B57: Facebook | C57: 45644 | D57: Carousel | E57: Explore the latest carousel on Myntra! Trendy styles await. | F57: 2946 | G57: 498 | H57: 367 | I57: 29460 | J57: 28527 | K57: 60 | L57: #StyleWithMyntra,#FashionDeals | M57: EndOfSeasonSale | N57: 12.94 | O57: 45453 | P57: 45478 | Q57: After Campaign
A58: P057 | B58: Twitter | C58: 45586 | D58: Video | E58: Explore the latest video on Myntra! Trendy styles await. | F58: 2825 | G58: 535 | H58: 295 | I58: 45200 | J58: 44739 | K58: 169 | L58: #StyleWithMyntra | M58: EndOfSeasonSale | N58: 8.09 | O58: 45453 | P58: 45478 | Q58: After Campaign
A59: P058 | B59: Instagram | C59: 45762 | D59: Reel | E59: Explore the latest reel on Myntra! Trendy styles await. | F59: 103 | G59: 770 | H59: 19 | I59: 1030 | J59: 410 | K59: 262 | L59: #MyntraSale | M59: MyntraFestiveEdit | N59: 86.6 | O59: 45570 | P59: 45601 | Q59: After Campaign
A60: P059 | B60: Instagram | C60: 45465 | D60: Text | E60: Explore the latest text on Myntra! Trendy styles await. | F60: 2180 | G60: 263 | H60: 387 | I60: 30520 | J60: 30059 | K60: 174 | L60: #FashionDeals | M60: FashionUpgrade | N60: 9.27 | O60: 45505 | P60: 45535 | Q60: Before Campaign
A61: P060 | B61: Instagram | C61: 45685 | D61: Video | E61: Explore the latest video on Myntra! Trendy styles await. | F61: 904 | G61: 973 | H61: 63 | I61: 11752 | J61: 11580 | K61: 84 | L61: #StyleWithMyntra | M61: FashionUpgrade | N61: 16.51 | O61: 45505 | P61: 45535 | Q61: After Campaign
A62: P061 | B62: Twitter | C62: 45540 | D62: Video | E62: Explore the latest video on Myntra! Trendy styles await. | F62: 4886 | G62: 983 | H62: 409 | I62: 43974 | J62: 43239 | K62: 65 | L62: #MyntraFashion | M62: FashionUpgrade | N62: 14.28 | O62: 45505 | P62: 45535 | Q62: After Campaign
A63: P062 | B63: Twitter | C63: 45618 | D63: Carousel | E63: Explore the latest carousel on Myntra! Trendy styles await. | F63: 53 | G63: 81 | H63: 379 | I63: 954 | J63: 7 | K63: 148 | L63: #FashionDeals | M63: MyntraFestiveEdit | N63: 53.77 | O63: 45570 | P63: 45601 | Q63: After Campaign
A64: P063 | B64: Twitter | C64: 45504 | D64: Carousel | E64: Explore the latest carousel on Myntra! Trendy styles await. | F64: 4507 | G64: 217 | H64: 13 | I64: 90140 | J64: 89591 | K64: 125 | L64: #MyntraSale | M64: FashionUpgrade | N64: 5.26 | O64: 45505 | P64: 45535 | Q64: Before Campaign
A65: P064 | B65: Facebook | C65: 45521 | D65: Image | E65: Explore the latest image on Myntra! Trendy styles await. | F65: 2878 | G65: 248 | H65: 416 | I65: 43170 | J65: 42667 | K65: 75 | L65: #FashionDeals,#MyntraTrend | M65: EndOfSeasonSale | N65: 8.2 | O65: 45453 | P65: 45478 | Q65: After Campaign
A66: P065 | B66: Instagram | C66: 45744 | D66: Story | E66: Explore the latest story on Myntra! Trendy styles await. | F66: 1881 | G66: 501 | H66: 99 | I66: 20691 | J66: 19987 | K66: 289 | L66: #FashionDeals | M66: EndOfSeasonSale | N66: 11.99 | O66: 45453 | P66: 45478 | Q66: After Campaign
A67: P066 | B67: Twitter | C67: 45499 | D67: Carousel | E67: Explore the latest carousel on Myntra! Trendy styles await. | F67: 432 | G67: 171 | H67: 280 | I67: 3024 | J67: 2285 | K67: 184 | L67: #MyntraFashion | M67: MyntraFestiveEdit | N67: 29.2 | O67: 45570 | P67: 45601 | Q67: Before Campaign
A68: P067 | B68: Facebook | C68: 45745 | D68: Carousel | E68: Explore the latest carousel on Myntra! Trendy styles await. | F68: 4712 | G68: 568 | H68: 127 | I68: 84816 | J68: 84691 | K68: 100 | L68: #FashionDeals | M68: FashionUpgrade | N68: 6.37 | O68: 45505 | P68: 45535 | Q68: After Campaign
... A301: P300 | B301: Twitter | C301: 45535 | D301: Carousel | E301: Explore the latest carousel on Myntra! Trendy styles await. | F301: 4494 | G301: 717 | H301: 45 | I301: 62916 | J301: 62688 | K301: 191 | L301: #MyntraFashion | M301: FashionUpgrade | N301: 8.35 | O301: 45505 | P301: 45535 | Q301: During Campaign

Sheet Engagment Summary
A1: Week_Start_Date | B1: Platform | C1: New_Followers | D1: Unfollows | E1: Follower_Gain | F1: Total_Followers | G1: Engagement_Rate | H1: Ad_Spend | I1: Followersgrowth_Rate(%) | J1: Campaign
A2: 45446 | B2: Instagram | C2: 1135 | D2: 88 | E2: =Engagment_Summary[[#This Row],[New_Followers]]-Engagment_Summary[[#This Row],[Unfollows]] -> 1047 | F2: 344084 | G2: 8.06 | H2: 5904 | I2: 0.30428616 | J2: {=IFERROR(INDEX('Campaign Data'!$A$2:$A$5,MATCH(1,(A2>='Campaign Data'!$B$2:$B$5)*(A2<='Campaign Data'!$C$2:$C$5),0)),"outside campaign")} -> outside campaign
A3: 45446 | B3: Facebook | C3: 1312 | D3: 310 | E3: =Engagment_Summary[[#This Row],[New_Followers]]-Engagment_Summary[[#This Row],[Unfollows]] -> 1002 | F3: 42654 | G3: 4.98 | H3: 9566 | I3: 2.3491349 | J3: {=IFERROR(INDEX('Campaign Data'!$A$2:$A$5,MATCH(1,(A3>='Campaign Data'!$B$2:$B$5)*(A3<='Campaign Data'!$C$2:$C$5),0)),"outside campaign")} -> outside campaign
A4: 45446 | B4: Twitter | C4: 584 | D4: 169 | E4: =Engagment_Summary[[#This Row],[New_Followers]]-Engagment_Summary[[#This Row],[Unfollows]] -> 415 | F4: 146834 | G4: 8.31 | H4: 26752 | I4: 0.28263209 | J4: {=IFERROR(INDEX('Campaign Data'!$A$2:$A$5,MATCH(1,(A4>='Campaign Data'!$B$2:$B$5)*(A4<='Campaign Data'!$C$2:$C$5),0)),"outside campaign")} -> outside campaign
A5: 45446 | B5: YouTube | C5: 1535 | D5: 445 | E5: =Engagment_Summary[[#This Row],[New_Followers]]-Engagment_Summary[[#This Row],[Unfollows]] -> 1090 | F5: 395536 | G5: 4.11 | H5: 30671 | I5: 0.27557542 | J5: {=IFERROR(INDEX('Campaign Data'!$A$2:$A$5,MATCH(1,(A5>='Campaign Data'!$B$2:$B$5)*(A5<='Campaign Data'!$C$2:$C$5),0)),"outside campaign")} -> outside campaign
A6: 45453 | B6: Instagram | C6: 656 | D6: 139 | E6: =Engagment_Summary[[#This Row],[New_Followers]]-Engagment_Summary[[#This Row],[Unfollows]] -> 517 | F6: 49157 | G6: 9.05 | H6: 9920 | I6: 1.0517322 | J6: {=IFERROR(INDEX('Campaign Data'!$A$2:$A$5,MATCH(1,(A6>='Campaign Data'!$B$2:$B$5)*(A6<='Campaign Data'!$C$2:$C$5),0)),"outside campaign")} -> EndOfSeasonSale
A7: 45453 | B7: Facebook | C7: 1697 | D7: 414 | E7: =Engagment_Summary[[#This Row],[New_Followers]]-Engagment_Summary[[#This Row],[Unfollows]] -> 1283 | F7: 316555 | G7: 2.37 | H7: 7924 | I7: 0.40530082 | J7: {=IFERROR(INDEX('Campaign Data'!$A$2:$A$5,MATCH(1,(A7>='Campaign Data'!$B$2:$B$5)*(A7<='Campaign Data'!$C$2:$C$5),0)),"outside campaign")} -> EndOfSeasonSale
A8: 45453 | B8: Twitter | C8: 436 | D8: 250 | E8: =Engagment_Summary[[#This Row],[New_Followers]]-Engagment_Summary[[#This Row],[Unfollows]] -> 186 | F8: 254347 | G8: 4.01 | H8: 8912 | I8: 0.073128443 | J8: {=IFERROR(INDEX('Campaign Data'!$A$2:$A$5,MATCH(1,(A8>='Campaign Data'!$B$2:$B$5)*(A8<='Campaign Data'!$C$2:$C$5),0)),"outside campaign")} -> EndOfSeasonSale
A9: 45453 | B9: YouTube | C9: 1197 | D9: 203 | E9: =Engagment_Summary[[#This Row],[New_Followers]]-Engagment_Summary[[#This Row],[Unfollows]] -> 994 | F9: 413878 | G9: 3.16 | H9: 21205 | I9: 0.24016739 | J9: {=IFERROR(INDEX('Campaign Data'!$A$2:$A$5,MATCH(1,(A9>='Campaign Data'!$B$2:$B$5)*(A9<='Campaign Data'!$C$2:$C$5),0)),"outside campaign")} -> EndOfSeasonSale
A10: 45460 | B10: Instagram | C10: 1048 | D10: 155 | E10: =Engagment_Summary[[#This Row],[New_Followers]]-Engagment_Summary[[#This Row],[Unfollows]] -> 893 | F10: 456946 | G10: 2.46 | H10: 11329 | I10: 0.19542791 | J10: {=IFERROR(INDEX('Campaign Data'!$A$2:$A$5,MATCH(1,(A10>='Campaign Data'!$B$2:$B$5)*(A10<='Campaign Data'!$C$2:$C$5),0)),"outside campaign")} -> EndOfSeasonSale
A11: 45460 | B11: Facebook | C11: 1753 | D11: 371 | E11: =Engagment_Summary[[#This Row],[New_Followers]]-Engagment_Summary[[#This Row],[Unfollows]] -> 1382 | F11: 169496 | G11: 8.11 | H11: 46670 | I11: 0.81535847 | J11: {=IFERROR(INDEX('Campaign Data'!$A$2:$A$5,MATCH(1,(A11>='Campaign Data'!$B$2:$B$5)*(A11<='Campaign Data'!$C$2:$C$5),0)),"outside campaign")} -> EndOfSeasonSale
A12: 45460 | B12: Twitter | C12: 1335 | D12: 40 | E12: =Engagment_Summary[[#This Row],[New_Followers]]-Engagment_Summary[[#This Row],[Unfollows]] -> 1295 | F12: 122732 | G12: 8.19 | H12: 22482 | I12: 1.0551445 | J12: {=IFERROR(INDEX('Campaign Data'!$A$2:$A$5,MATCH(1,(A12>='Campaign Data'!$B$2:$B$5)*(A12<='Campaign Data'!$C$2:$C$5),0)),"outside campaign")} -> EndOfSeasonSale
A13: 45460 | B13: YouTube | C13: 403 | D13: 66 | E13: =Engagment_Summary[[#This Row],[New_Followers]]-Engagment_Summary[[#This Row],[Unfollows]] -> 337 | F13: 382851 | G13: 3.49 | H13: 24313 | I13: 0.0880238 | J13: {=IFERROR(INDEX('Campaign Data'!$A$2:$A$5,MATCH(1,(A13>='Campaign Data'!$B$2:$B$5)*(A13<='Campaign Data'!$C$2:$C$5),0)),"outside campaign")} -> EndOfSeasonSale
... A201: 45789 | B201: YouTube | C201: 119 | D201: 456 | E201: =Engagment_Summary[[#This Row],[New_Followers]]-Engagment_Summary[[#This Row],[Unfollows]] -> -337 | F201: 82558 | G201: 6.81 | H201: 12174 | I201: -0.40819787 | J201: {=IFERROR(INDEX('Campaign Data'!$A$2:$A$5,MATCH(1,(A201>='Campaign Data'!$B$2:$B$5)*(A201<='Campaign Data'!$C$2:$C$5),0)),"outside campaign")} -> outside campaign
G204: =AVERAGEIF(Engagment_Summary[Campaign],"EndOfSeasonSale",Engagment_Summary[Ad_Spend]) -> 20146.875

Sheet Campaign Data
A1: Campaign_Name | B1: Start_Date | C1: End_Date | D1: Objective | E1: Total_Budget | F1: Target_Platforms
A2: EndOfSeasonSale | B2: 45453 | C2: 45478 | D2: Seasonal Clearance Promotion | E2: 180000 | F2: Instagram,Facebook
A3: FashionUpgrade | B3: 45505 | C3: 45535 | D3: Customer Engagement | E3: 160000 | F3: Instagram,YouTube
A4: MyntraFestiveEdit | B4: 45570 | C4: 45601 | D4: Festive Collection Launch | E4: 220000 | F4: Facebook,Instagram
A5: StyleRevolution | B5: 45667 | C5: 45698 | D5: Brand Awareness & Growth | E5: 200000 | F5: Instagram,Twitter

Sheet Task2
FK21: PLATFORM | FL21: SUM OF LIKES | FM21: SUM OF SHARES | FN21: SUM OF COMMENTS | FO21: SUM OF IMPRSSIONS
C22: PLATFORM | D22: SUM OF LIKES | E22: SUM OF SHARES | F22: SUM OF COMMENTS | G22: SUM OF IMPRSSIONS | FK22: YouTube | FL22: =SUMIF(Post_Engagement[Platform],"Youtube",Post_Engagement[Likes]) -> 171549 | FM22: =SUMIF(Post_Engagement[Platform],"Youtube",Post_Engagement[Shares]) -> 28572 | FN22: =SUMIF(Post_Engagement[Platform],"Youtube",Post_Engagement[Comments]) -> 12820 | FO22: =SUMIF(Post_Engagement[Platform],"Youtube",Post_Engagement[Impressions]) -> 2268407
C23: YouTube | D23: =SUMIF(Post_Engagement[Platform],"Youtube",Post_Engagement[Likes]) -> 171549 | E23: =SUMIF(Post_Engagement[Platform],"Youtube",Post_Engagement[Shares]) -> 28572 | F23: =SUMIF(Post_Engagement[Platform],"Youtube",Post_Engagement[Comments]) -> 12820 | G23: =SUMIF(Post_Engagement[Platform],"Youtube",Post_Engagement[Impressions]) -> 2268407 | FK23: Instagram | FL23: =SUMIF(Post_Engagement[Platform],"Instagram",Post_Engagement[Likes]) -> 204284 | FM23: =SUMIF(Post_Engagement[Platform],"Instagram",Post_Engagement[Shares]) -> 41444 | FN23: =SUMIF(Post_Engagement[Platform],"Instagram",Post_Engagement[Comments]) -> 17851 | FO23: =SUMIF(Post_Engagement[Platform],"Instagram",Post_Engagement[Impressions]) -> 2325756
C24: Instagram | D24: =SUMIF(Post_Engagement[Platform],"Instagram",Post_Engagement[Likes]) -> 204284 | E24: =SUMIF(Post_Engagement[Platform],"Instagram",Post_Engagement[Shares]) -> 41444 | F24: =SUMIF(Post_Engagement[Platform],"Instagram",Post_Engagement[Comments]) -> 17851 | G24: =SUMIF(Post_Engagement[Platform],"Instagram",Post_Engagement[Impressions]) -> 2325756 | FK24: Facebook | FL24: =SUMIF(Post_Engagement[Platform],"Facebook",Post_Engagement[Likes]) -> 242761 | FM24: =SUMIF(Post_Engagement[Platform],"Facebook",Post_Engagement[Shares]) -> 39181 | FN24: =SUMIF(Post_Engagement[Platform],"Facebook",Post_Engagement[Comments]) -> 23300 | FO24: =SUMIF(Post_Engagement[Platform],"Facebook",Post_Engagement[Impressions]) -> 3239154
C25: Facebook | D25: =SUMIF(Post_Engagement[Platform],"Facebook",Post_Engagement[Likes]) -> 242761 | E25: =SUMIF(Post_Engagement[Platform],"Facebook",Post_Engagement[Shares]) -> 39181 | F25: =SUMIF(Post_Engagement[Platform],"Facebook",Post_Engagement[Comments]) -> 23300 | G25: =SUMIF(Post_Engagement[Platform],"Facebook",Post_Engagement[Impressions]) -> 3239154 | FK25: Twitter | FL25: =SUMIF(Post_Engagement[Platform],"Twitter",Post_Engagement[Likes]) -> 201397 | FM25: =SUMIF(Post_Engagement[Platform],"Twitter",Post_Engagement[Shares]) -> 33728 | FN25: =SUMIF(Post_Engagement[Platform],"Twitter",Post_Engagement[Comments]) -> 20880 | FO25: =SUMIF(Post_Engagement[Platform],"Twitter",Post_Engagement[Impressions]) -> 2560836
C26: Twitter | D26: =SUMIF(Post_Engagement[Platform],"Twitter",Post_Engagement[Likes]) -> 201397 | E26: =SUMIF(Post_Engagement[Platform],"Twitter",Post_Engagement[Shares]) -> 33728 | F26: =SUMIF(Post_Engagement[Platform],"Twitter",Post_Engagement[Comments]) -> 20880 | G26: =SUMIF(Post_Engagement[Platform],"Twitter",Post_Engagement[Impressions]) -> 2560836 | FK26: Total | FL26: =SUM(FL22:FL25) -> 819991 | FM26: =SUM(FM22:FM25) -> 142925 | FN26: =SUM(FN22:FN25) -> 74851 | FO26: =SUM(FO22:FO25) -> 10394153
C27: Total | D27: =SUM(D23:D26) -> 819991 | E27: =SUM(E23:E26) -> 142925 | F27: =SUM(F23:F26) -> 74851 | G27: =SUM(G23:G26) -> 10394153
G28: )
D29: ENGAGEMENT RATE PER PLATFORM
D30: Engagement rate for you tube | E30: =SUM(D23:F23)/G23 -> 0.093872484
D31: Engagement rate for Instagram | E31: =SUM(D24:F24)/G24 -> 0.11333046
D32: Engagement rate for Facebook | E32: =SUM(D25:F25)/G25 -> 0.0942351
D33: Engagement rate for Twitter | E33: =SUM(D26:F26)/G26 -> 0.099969307
D34: Engagement rate (overall) | E34: =SUM(D27:F27)/G27 -> 0.09984142
C54: Post ID | D54: Platform | E54: Date | F54: Content Type | G54: Post Text | H54: Likes | I54: Shares | J54: Comments | K54: Impressions | L54: Reach | M54: Clicks | N54: Hashtags Used | O54: Campaign_Name | P54: Engagement_Rate
C55: P220 | D55: Instagram | E55: 45445 | F55: Story | G55: Explore the latest story on Myntra! Trendy styles await. | H55: 84 | I55: 897 | J55: 85 | K55: 588 | L55: 8 | M55: 12 | N55: #StyleWithMyntra | O55: EndOfSeasonSale | P55: 181.29
C56: P058 | D56: Instagram | E56: 45762 | F56: Reel | G56: Explore the latest reel on Myntra! Trendy styles await. | H56: 103 | I56: 770 | J56: 19 | K56: 1030 | L56: 410 | M56: 262 | N56: #MyntraSale | O56: MyntraFestiveEdit | P56: 86.6
C57: P232 | D57: Twitter | E57: 45776 | F57: Story | G57: Explore the latest story on Myntra! Trendy styles await. | H57: 249 | I57: 592 | J57: 230 | K57: 1494 | L57: 1044 | M57: 201 | N57: #MyntraFashion,#MyntraTrend | O57: StyleRevolution | P57: 71.69
C58: P178 | D58: Instagram | E58: 45603 | F58: Video | G58: Explore the latest video on Myntra! Trendy styles await. | H58: 129 | I58: 643 | J58: 136 | K58: 1290 | L58: 839 | M58: 238 | N58: #StyleWithMyntra,#FashionDeals | O58: StyleRevolution | P58: 70.39
C59: P175 | D59: Instagram | E59: 45674 | F59: Reel | G59: Explore the latest reel on Myntra! Trendy styles await. | H59: 142 | I59: 784 | J59: 183 | K59: 1704 | L59: 995 | M59: 154 | N59: #MyntraSale | O59: FashionUpgrade | P59: 65.08
C60: P062 | D60: Twitter | E60: 45618 | F60: Carousel | G60: Explore the latest carousel on Myntra! Trendy styles await. | H60: 53 | I60: 81 | J60: 379 | K60: 954 | L60: 7 | M60: 148 | N60: #FashionDeals | O60: MyntraFestiveEdit | P60: 53.77
C61: P264 | D61: Twitter | E61: 45687 | F61: Image | G61: Explore the latest image on Myntra! Trendy styles await. | H61: 59 | I61: 163 | J61: 93 | K61: 590 | L61: 475 | M61: 293 | N61: #MyntraTrend | O61: StyleRevolution | P61: 53.39
C62: P143 | D62: YouTube | E62: 45567 | F62: Carousel | G62: Explore the latest carousel on Myntra! Trendy styles await. | H62: 80 | I62: 362 | J62: 80 | K62: 1040 | L62: 349 | M62: 117 | N62: #MyntraFashion,#StyleWithMyntra | O62: EndOfSeasonSale | P62: 50.19
C63: P210 | D63: YouTube | E63: 45707 | F63: Image | G63: Explore the latest image on Myntra! Trendy styles await. | H63: 257 | I63: 966 | J63: 398 | K63: 3341 | L63: 2753 | M63: 287 | N63: #MyntraTrend,#MyntraSale | O63: FashionUpgrade | P63: 48.52
C64: P070 | D64: Facebook | E64: 45749 | F64: Video | G64: Explore the latest video on Myntra! Trendy styles await. | H64: 199 | I64: 772 | J64: 400 | K64: 3582 | L64: 2988 | M64: 43 | N64: #MyntraTrend | O64: FashionUpgrade | P64: 38.27
C73: Row Labels | D73: Sum of Likes | E73: Sum of Shares | F73: Sum of Comments
C74: Facebook | D74: 28947 | E74: 3171 | F74: 2263
C75: Instagram | D75: 25770 | E75: 5912 | F75: 2128
C76: Twitter | D76: 29593 | E76: 6326 | F76: 3299
C77: YouTube | D77: 31285 | E77: 5586 | F77: 2589
C78: Grand Total | D78: 115595 | E78: 20995 | F78: 10279
C90: Hashtags | D90: Average clicks per pot by hashtag
C91: #FashionDeals | D91: 152.575
C92: #MyntraFashion | D92: 140.96386
C93: #MyntraSale | D93: 149.70103
C94: #MyntraTrend | D94: 165.27174
C95: #StyleWithMyntra | D95: 146.16346
C96: Grand Total | D96: 150.94956
C102: Row Labels | D102: Average of Reach | E102: Average of Clicks | F102: Average of Engagement_Rate
C103: #FashionDeals | D103: 34086.812 | E103: 152.575 | F103: 13.661
...

Sheet task3
D7: Platform | E7: Average engagement rate
D8: YouTube | E8: =AVERAGEIF(Engagment_Summary[Platform],"YouTube",Engagment_Summary[Engagement_Rate]) -> 5.5588
D9: Instagram | E9: =AVERAGEIF(Engagment_Summary[Platform],"Instagram",Engagment_Summary[Engagement_Rate]) -> 5.7156
D10: Facebook | E10: =AVERAGEIF(Engagment_Summary[Platform],"Facebook",Engagment_Summary[Engagement_Rate]) -> 5.6486
D11: Twitter | E11: =AVERAGEIF(Engagment_Summary[Platform],"Twitter",Engagment_Summary[Engagement_Rate]) -> 5.6558
D12: Overall | E12: =AVERAGE(Engagment_Summary[Engagement_Rate]) -> 5.6447
D14: platform | E14: use
D15: YouTube | E15: Product demos and Education
D16: Instagram | E16: Brand Visibility and Engagement
D17: Facebook | E17: Reach and promotions
D18: Twitter | E18: Trends and annoucement
H29: Row Labels | I29: Average of Followersgrowth_Rate
H30: Facebook | I30: 0.54649907
H31: Instagram | I31: 0.57625321
H32: Twitter | I32: 0.92800257
H33: YouTube | I33: 0.90210666
H34: Grand Total | I34: 0.73821538
H52: Row Labels | I52: Average of Ad_Spend | J52: Average of Engagement_Rate
H53: Facebook | I53: 27590.78 | J53: 5.6486
H54: Instagram | I54: 23287.46 | J54: 5.7156
H55: Twitter | I55: 21207.14 | J55: 5.6558
H56: YouTube | I56: 24572.94 | J56: 5.5588
H57: Grand Total | I57: 24164.58 | J57: 5.6447
D69: Platform | E69: Insights
D70: Instagram | E70: Highest Average Engagement rate with strong cost efficiency making it the most eeffective platform for engagement driven-campaigns.
D71: Twitter | E71: Highest Average Follower growth rate combine with the lowest ad spend making it the most cost effectivee platform for audience growth.
D72: YouTube | E72: Strong follower growth and suitable for product demonstrations, but relatively higher ad spend reduces engagement eiciency.
D73: Facebook | E73: Lowest Average Followers Growth rate, also below the Overall average comparatively lower ROI and higher cost.

Sheet Task4
A6: Row Labels | B6: Count of Post ID
A7: #FashionDeals | B7: 80
A8: #MyntraFashion | B8: 83
A9: #MyntraSale | B9: 97
A10: #MyntraTrend | B10: 92
A11: #StyleWithMyntra | B11: 104
A12: Grand Total | B12: 456
A32: Row Labels | B32: Average of Reach | C32: Average of Clicks | D32: Average of Engagement_Rate
A33: #FashionDeals | B33: 34086.812 | C33: 152.575 | D33: 13.661
A34: #MyntraFashion | B34: 33520.277 | C34: 140.96386 | D34: 14.549639
A35: #MyntraSale | B35: 32666.031 | C35: 149.70103 | D35: 14.917423
A36: #MyntraTrend | B36: 35209.076 | C36: 165.27174 | D36: 14.353696
A37: #StyleWithMyntra | B37: 34492.471 | C37: 146.16346 | D37: 15.618558
A38: Grand Total | B38: 34000.406 | C38: 150.94956 | D38: 14.676228
A72: Row Labels | B72: Average of Engagement_Rate | C72: Average of Reach | D72: Average of Clicks
A73: Carousel | B73: 14.815254 | C73: 35335.915 | D73: 156.81356
A74: Image | B74: 13.68746 | C74: 35303.238 | D74: 163.5873
A75: Reel | B75: 15.615532 | C75: 34693.489 | D75: 152.65957
A76: Story | B76: 18.426087 | C76: 31639.543 | D76: 131.69565
A77: Text | B77: 11.750714 | C77: 34686.214 | D77: 163.40476
A78: Video | B78: 14.815581 | C78: 32089.907 | D78: 132.83721
A79: Grand Total | B79: 14.828467 | C79: 34105.41 | D79: 151.22
A115: Row Labels | B115: Average of Engagement_Rate | C115: Average of Reach | D115: Average of Clicks
A116: Facebook | B116: 12.11 | C116: 37871.143 | D116: 173.85714
A117: Instagram | B117: 14.9575 | C117: 28856.821 | D117: 148.71429
A118: Twitter | B118: 15.4016 | C118: 35970.96 | D118: 135.76
A119: YouTube | B119: 18.122222 | C119: 36370.389 | D119: 166.5
A120: Grand Total | B120: 15.047391 | C120: 34317.674 | D120: 154.41304

Sheet Task5
A5: Row Labels | B5: Sum of Impressions | C5: Sum of Comments | D5: Sum of Shares | E5: Sum of Likes | F5: Sum of Clicks
A6: EndOfSeasonSale | B6: 2886292 | C6: 21636 | D6: 41353 | E6: 232785 | F6: 12376
A7: FashionUpgrade | B7: 2788367 | C7: 18692 | D7: 33921 | E7: 212431 | F7: 11191
A8: MyntraFestiveEdit | B8: 2611652 | C8: 18550 | D8: 39123 | E8: 198666 | F8: 12464
A9: StyleRevolution | B9: 2107842 | C9: 15973 | D9: 28528 | E9: 176109 | F9: 9335
A10: Grand Total | B10: 10394153 | C10: 74851 | D10: 142925 | E10: 819991 | F10: 45366
A15: Row Labels | B15: Average of Impressions | C15: Average of Comments | D15: Average of Likes | E15: Average of Clicks | F15: Average of Shares
A16: EndOfSeasonSale | B16: 34774.602 | C16: 260.6747 | D16: 2804.6386 | E16: 149.10843 | F16: 498.22892
A17: FashionUpgrade | B17: 38727.319 | C17: 259.61111 | D17: 2950.4306 | E17: 155.43056 | F17: 471.125
A18: MyntraFestiveEdit | B18: 33482.718 | C18: 237.82051 | D18: 2547 | E18: 159.79487 | F18: 501.57692
A19: StyleRevolution | B19: 31460.328 | C19: 238.40299 | D19: 2628.4925 | E19: 139.32836 | F19: 425.79104
A20: Grand Total | B20: 34647.177 | C20: 249.50333 | D20: 2733.3033 | E20: 151.22 | F20: 476.41667
A27: Campaign Name | B27: Sum of Likes | C27: Sum of Shares | D27: Sum of Comments
A28: After Campaign | B28: 56039 | C28: 8709 | D28: 5313
A29: Before Campaign | B29: 106370 | C29: 18279 | D29: 9184
A30: During Campaign | B30: 13700 | C30: 1540 | D30: 1476
A31: Grand Total | B31: 176109 | C31: 28528 | D31: 15973
G32: Formula Used:
A33: Total Engagement Before | B33: Total Engagement During | C33: Total Engagement After | D33: Engagement Upliftment During VS Before (%) | G33: Engagement upliftmnt=(Engag. during-Engag. Bfore)/Engag Before
A34: =GETPIVOTDATA("Sum of Likes",$A$27,"Custom","Before Campaign")+GETPIVOTDATA("Sum of Shares",$A$27,"Custom","Before Campaign")+GETPIVOTDATA("Sum of Comments",$A$27,"Custom","Before Campaign") -> 133833 | B34: =GETPIVOTDATA("Sum of Likes",$A$27,"Custom","During Campaign")+GETPIVOTDATA("Sum of Shares",$A$27,"Custom","During Campaign")+GETPIVOTDATA("Sum of Comments",$A$27,"Custom","During Campaign") -> 16716 | C34: =GETPIVOTDATA("Sum of Likes",$A$27,"Custom","After Campaign")+GETPIVOTDATA("Sum of Shares",$A$27,"Custom","After Campaign")+GETPIVOTDATA("Sum of Comments",$A$27,"Custom","After Campaign") -> 70061 | D34: =((B34-A34)/A34)*100 -> -87.509807
A43: Sum of Ad_Spend
A44: 4832916
A45: Column1 | B45: Column2 | C45: Column3 | D45: Column4
A46: Campign Name | B46: Budget allocation | C46: Engag. During Campaign | D46: Engagement per Rupee
A47: EndOfSeassonSale | B47: 180000 | C47: 20185 | D47: =Table10[[#This Row],[Column3]]/Table10[[#This Row],[Column2]] -> 0.11213889
A48: FashionUpgrade | B48: 160000 | C48: 29029 | D48: =Table10[[#This Row],[Column3]]/Table10[[#This Row],[Column2]] -> 0.18143125
A49: MyntraFestiveEdit | B49: 220000 | C49: 25499 | D49: =Table10[[#This Row],[Column3]]/Table10[[#This Row],[Column2]] -> 0.11590455
A50: Style Revolution | B50: 200000 | C50: 16716 | D50: =Table10[[#This Row],[Column3]]/Table10[[#This Row],[Column2]] -> 0.08358
A56: Row Labels | B56: Average of Followersgrowth_Rate
A57: EndOfSeasonSale | B57: 0.79857711
A58: FashionUpgrade | B58: 0.28457351
A59: MyntraFestiveEdit | B59: 0.46940716
A60: outside campaign | B60: 0.84528528
A61: StyleRevolution | B61: 0.63640033
A62: Grand Total | B62: 0.73821538

Sheet Task6
A5: Average of Followersgrowth_Rate | B5: Column Labels
A6: Row Labels | B6: Facebook | C6: Instagram | D6: Twitter | E6: YouTube | F6: Grand Total
A7: 45446 | B7: 2.3491349 | C7: 0.30428616 | D7: 0.28263209 | E7: 0.27557542 | F7: 0.80290714
A8: 45453 | B8: 0.40530082 | C8: 1.0517322 | D8: 0.073128443 | E8: 0.24016739 | F8: 0.44258221
A9: 45460 | B9: 0.81535847 | C9: 0.19542791 | D9: 1.0551445 | E9: 0.0880238 | F9: 0.53848868
A10: 45467 | B10: 6.3510173 | C10: 1.7636833 | D10: 0.27980605 | E10: -0.028860774 | F10: 2.0914115
A11: 45474 | B11: 0.029088265 | C11: -0.052211602 | D11: 0.43037694 | E11: 0.080050669 | F11: 0.12182607
A12: 45481 | B12: 0.12276812 | C12: 2.8717174 | D12: 0.14032477 | E12: 0.21994574 | F12: 0.838689
A13: 45488 | B13: -0.049009939 | C13: 1.1967386 | D13: 0.18982133 | E13: 0.10211701 | F13: 0.35991676
A14: 45495 | B14: 0.32572738 | C14: 0.033557614 | D14: 0.66371458 | E14: 0.10340418 | F14: 0.28160094
A15: 45502 | B15: -0.073097735 | C15: 2.2861731 | D15: 0.51986619 | E15: 0.76001216 | F15: 0.87323843
A16: 45509 | B16: -0.15755714 | C16: 0.080371169 | D16: 0.072889861 | E16: 0.09948542 | F16: 0.023797326
A17: 45516 | B17: 0.43366319 | C17: 0.27085701 | D17: 0.0085080355 | E17: 1.0113483 | F17: 0.43109413
A18: 45523 | B18: 0.5752376 | C18: 0.023352712 | D18: 0.88256341 | E18: 0.2172844 | F18: 0.42460953
... A56: 45789 | B56: 0.11156187 | C56: 0.35361872 | D56: 0.058952702 | E56: -0.40819787 | F56: 0.028983854
A57: Grand Total | B57: 0.54649907 | C57: 0.57625321 | D57: 0.92800257 | E57: 0.90210666 | F57: 0.73821538
A86: Row Labels | B86: Sum of Follower_Gain
A87: 45446 | B87: 3554
A88: 45453 | B88: 2980
A89: 45460 | B89: 3907
A90: 45467 | B90: 3011
A91: 45474 | B91: 1293
A92: 45481 | B92: 3042
A93: 45488 | B93: 2270
A94: 45495 | B94: 2753
A95: 45502 | B95: 2193
A96: 45509 | B96: 802
A97: 45516 | B97: 3728
A98: 45523 | B98: 2989
... A136: 45789 | B136: 1995
A137: Grand Total | B137: 160105
A142: Row Labels | B142: Sum of Follower_Gain
A143: 45446 | B143: 3554
A144: 45453 | B144: 2980
A145: 45460 | B145: 3907
A146: 45467 | B146: 3011
A147: 45474 | B147: 1293
A148: 45481 | B148: 3042
A149: 45488 | B149: 2270
A150: 45495 | B150: 2753
...

Sheet video link
A1: https://www.loom.com/share/ce7c98d0552b47408140d9f59d9344d0
A5: https://www.loom.com/share/ce7c98d0552b47408140d9f59d9344d0
